<?xml version="1.0"?>
<robot name="risk_aware_arm">

  <!-- ===================== -->
  <!-- MATERIAL DEFINITIONS -->
  <!-- ===================== -->
  <material name="grey">
    <color rgba="0.6 0.6 0.6 1.0"/>
  </material>

  <material name="blue">
    <color rgba="0.2 0.2 0.8 1.0"/>
  </material>

  <!-- ===================== -->
  <!-- BASE LINK -->
  <!-- ===================== -->
  <link name="base_link">
    <visual>
      <geometry>
        <box size="0.3 0.3 0.1"/>
      </geometry>
      <material name="grey"/>
    </visual>

    <collision>
      <geometry>
        <box size="0.3 0.3 0.1"/>
      </geometry>
    </collision>

    <inertial>
      <origin xyz="0 0 0" rpy="0 0 0"/>
      <mass value="5.0"/>
      <inertia ixx="0.1" ixy="0" ixz="0"
               iyy="0.1" iyz="0"
               izz="0.1"/>
    </inertial>
  </link>

  <!-- ===================== -->
  <!-- LINK 1 -->
  <!-- ===================== -->
  <link name="link1">
    <visual>
      <geometry>
        <cylinder length="0.4" radius="0.05"/>
      </geometry>
      <material name="blue"/>
    </visual>

    <collision>
      <geometry>
        <cylinder length="0.4" radius="0.05"/>
      </geometry>
    </collision>

    <inertial>
      <origin xyz="0 0 0.2" rpy="0 0 0"/>
      <mass value="2.0"/>
      <inertia ixx="0.02" ixy="0" ixz="0"
               iyy="0.02" iyz="0"
               izz="0.01"/>
    </inertial>
  </link>

  <joint name="joint1" type="revolute">
    <parent link="base_link"/>
    <child link="link1"/>
    <origin xyz="0 0 0.05" rpy="0 0 0"/>
    <axis xyz="0 0 1"/>
    <limit lower="-3.14" upper="3.14" effort="10" velocity="1"/>
  </joint>

  <!-- ===================== -->
  <!-- LINK 2 -->
  <!-- ===================== -->
  <link name="link2">
    <visual>
      <geometry>
        <cylinder length="0.4" radius="0.05"/>
      </geometry>
      <material name="grey"/>
    </visual>

    <collision>
      <geometry>
        <cylinder length="0.4" radius="0.05"/>
      </geometry>
    </collision>

    <inertial>
      <origin xyz="0 0 0.2" rpy="0 0 0"/>
      <mass value="2.0"/>
      <inertia ixx="0.02" ixy="0" ixz="0"
               iyy="0.02" iyz="0"
               izz="0.01"/>
    </inertial>
  </link>

  <joint name="joint2" type="revolute">
    <parent link="link1"/>
    <child link="link2"/>
    <origin xyz="0 0 0.4" rpy="0 0 0"/>
    <axis xyz="0 1 0"/>
    <limit lower="-1.57" upper="1.57" effort="10" velocity="1"/>
  </joint>

  <!-- ===================== -->
  <!-- LINK 3 -->
  <!-- ===================== -->
  <link name="link3">
    <visual>
      <geometry>
        <cylinder length="0.3" radius="0.04"/>
      </geometry>
      <material name="blue"/>
    </visual>

    <collision>
      <geometry>
        <cylinder length="0.3" radius="0.04"/>
      </geometry>
    </collision>

    <inertial>
      <origin xyz="0 0 0.15" rpy="0 0 0"/>
      <mass value="1.5"/>
      <inertia ixx="0.015" ixy="0" ixz="0"
               iyy="0.015" iyz="0"
               izz="0.008"/>
    </inertial>
  </link>

  <joint name="joint3" type="revolute">
    <parent link="link2"/>
    <child link="link3"/>
    <origin xyz="0 0 0.4" rpy="0 0 0"/>
    <axis xyz="0 1 0"/>
    <limit lower="-1.57" upper="1.57" effort="10" velocity="1"/>
  </joint>

  <!-- ===================== -->
  <!-- LINK 4 -->
  <!-- ===================== -->
  <link name="link4">
    <visual>
      <geometry>
        <cylinder length="0.2" radius="0.035"/>
      </geometry>
      <material name="grey"/>
    </visual>

    <collision>
      <geometry>
        <cylinder length="0.2" radius="0.035"/>
      </geometry>
    </collision>

    <inertial>
      <origin xyz="0 0 0.1" rpy="0 0 0"/>
      <mass value="1.0"/>
      <inertia ixx="0.01" ixy="0" ixz="0"
               iyy="0.01" iyz="0"
               izz="0.005"/>
    </inertial>
  </link>

  <joint name="joint4" type="revolute">
    <parent link="link3"/>
    <child link="link4"/>
    <origin xyz="0 0 0.3" rpy="0 0 0"/>
    <axis xyz="1 0 0"/>
    <limit lower="-3.14" upper="3.14" effort="10" velocity="1"/>
  </joint>

  <!-- ===================== -->
  <!-- TOOL -->
  <!-- ===================== -->
  <link name="tool0">
    <visual>
      <geometry>
        <sphere radius="0.05"/>
      </geometry>
      <material name="blue"/>
    </visual>

    <collision>
      <geometry>
        <sphere radius="0.05"/>
      </geometry>
    </collision>

    <inertial>
      <origin xyz="0 0 0" rpy="0 0 0"/>
      <mass value="0.5"/>
      <inertia ixx="0.005" ixy="0" ixz="0"
               iyy="0.005" iyz="0"
               izz="0.005"/>
    </inertial>
  </link>

  <joint name="joint5" type="revolute">
    <parent link="link4"/>
    <child link="tool0"/>
    <origin xyz="0 0 0.2" rpy="0 0 0"/>
    <axis xyz="0 0 1"/>
    <limit lower="-3.14" upper="3.14" effort="5" velocity="1"/>
  </joint>

</robot>
